Workbook

Sheet Instructions
A1: ConversaFlow — Arabic wording review
A2: Thank you for reviewing the Arabic text of the ConversaFlow web app. Each row on the "Review" sheet is one piece of text, grouped by screen.
A4: What to do
A5: 1. Fill in your name and the date below.
A6: 2. On the Review sheet, read the English (column E) and the current Arabic (column F). Screenshots of most screens are listed in column C.
A7: 3. In column G choose OK, Change or Question.
A8: 4. If you choose Change, write the corrected Arabic in column H. Keep any word in curly brackets, for example {name}, exactly as it is.
A9: 5. Use column I for any comment or question (Arabic or English).
A10: 6. Only the yellow cells are yours to edit. Please do not change the grey columns.
A11: 7. The Summary sheet shows how many rows are left on each screen.
A13: Style guide
A14: • Modern Standard Arabic suitable for Gulf business users (Saudi Arabia and UAE).
... A20: Example of a completed row (illustration only — not on the Review sheet)
A21: Screen | B21: English | C21: Arabic now | D21: Your verdict | E21: Corrected Arabic | F21: Comment
A22: Sign-in | B22: Forgot password? | C22: نسيت كلمة المرور؟ | D22: Change | E22: هل نسيت كلمة المرور؟ | F22: More natural as a question in Gulf usage
A24: Reviewer name
A25: Review date
A26: Reviewer role / company
A28: Legend: yellow = for the reviewer to fill in; grey = source text, do not edit.

Sheet Review
A1: # | B1: Screen | C1: Screenshots (Arabic) | D1: Key | E1: English (source) | F1: Arabic now | G1: Your verdict | H1: Corrected Arabic | I1: Comment / question | J1: Must keep | K1: Check | L1: Developer: applied
A2: 1 | B2: Sign-in | C2: docs/reports/evidence/ui/ar-mobile-sign-in.png docs/reports/evidence/ui/ar-desktop-sign-in.png | D2: brand.tagline | E2: One Platform. Every Conversation. Every Customer. | F2: منصة واحدة. كل محادثة. كل عميل. | K2: =IF(G2="","To review",IF(AND(G2="Change",H2=""),"Add corrected text",IF(AND(H2<>"",J2<>"",ISERROR(SEARCH(J2,H2))),"Keep "&J2,""))) -> To review
A3: 2 | B3: Sign-in | C3: docs/reports/evidence/ui/ar-mobile-sign-in.png docs/reports/evidence/ui/ar-desktop-sign-in.png | D3: features.ai | E3: Ready for AI automation | F3: جاهزة لأتمتة الذكاء الاصطناعي | K3: =IF(G3="","To review",IF(AND(G3="Change",H3=""),"Add corrected text",IF(AND(H3<>"",J3<>"",ISERROR(SEARCH(J3,H3))),"Keep "&J3,""))) -> To review
A4: 3 | B4: Sign-in | C4: docs/reports/evidence/ui/ar-mobile-sign-in.png docs/reports/evidence/ui/ar-desktop-sign-in.png | D4: features.gulf | E4: Built for the Gulf and beyond | F4: مصممة للخليج والعالم | K4: =IF(G4="","To review",IF(AND(G4="Change",H4=""),"Add corrected text",IF(AND(H4<>"",J4<>"",ISERROR(SEARCH(J4,H4))),"Keep "&J4,""))) -> To review
A5: 4 | B5: Sign-in | C5: docs/reports/evidence/ui/ar-mobile-sign-in.png docs/reports/evidence/ui/ar-desktop-sign-in.png | D5: features.secure | E5: Secure and reliable | F5: آمنة وموثوقة | K5: =IF(G5="","To review",IF(AND(G5="Change",H5=""),"Add corrected text",IF(AND(H5<>"",J5<>"",ISERROR(SEARCH(J5,H5))),"Keep "&J5,""))) -> To review
A6: 5 | B6: Sign-in | C6: docs/reports/evidence/ui/ar-mobile-sign-in.png docs/reports/evidence/ui/ar-desktop-sign-in.png | D6: features.separate | E6: Each company fully separated | F6: فصل تام لبيانات كل شركة | K6: =IF(G6="","To review",IF(AND(G6="Change",H6=""),"Add corrected text",IF(AND(H6<>"",J6<>"",ISERROR(SEARCH(J6,H6))),"Keep "&J6,""))) -> To review
A7: 6 | B7: Sign-in | C7: docs/reports/evidence/ui/ar-mobile-sign-in.png docs/reports/evidence/ui/ar-desktop-sign-in.png | D7: lang.switchLabel | E7: Switch to Arabic | F7: التبديل إلى الإنجليزية | K7: =IF(G7="","To review",IF(AND(G7="Change",H7=""),"Add corrected text",IF(AND(H7<>"",J7<>"",ISERROR(SEARCH(J7,H7))),"Keep "&J7,""))) -> To review
A8: 7 | B8: Sign-in | C8: docs/reports/evidence/ui/ar-mobile-sign-in.png docs/reports/evidence/ui/ar-desktop-sign-in.png | D8: lang.switchTo | E8: العربية | F8: English | I8: Button that switches to the OTHER language, so in Arabic it correctly reads "English". | K8: =IF(G8="","To review",IF(AND(G8="Change",H8=""),"Add corrected text",IF(AND(H8<>"",J8<>"",ISERROR(SEARCH(J8,H8))),"Keep "&J8,""))) -> To review
A9: 8 | B9: Sign-in | C9: docs/reports/evidence/ui/ar-mobile-sign-in.png docs/reports/evidence/ui/ar-desktop-sign-in.png | D9: signIn.badCode | E9: That code is not correct. Please try again. | F9: الرمز غير صحيح. يُرجى المحاولة مرة أخرى. | K9: =IF(G9="","To review",IF(AND(G9="Change",H9=""),"Add corrected text",IF(AND(H9<>"",J9<>"",ISERROR(SEARCH(J9,H9))),"Keep "&J9,""))) -> To review
A10: 9 | B10: Sign-in | C10: docs/reports/evidence/ui/ar-mobile-sign-in.png docs/reports/evidence/ui/ar-desktop-sign-in.png | D10: signIn.code | E10: Verification code | F10: رمز التحقق | K10: =IF(G10="","To review",IF(AND(G10="Change",H10=""),"Add corrected text",IF(AND(H10<>"",J10<>"",ISERROR(SEARCH(J10,H10))),"Keep "&J10,""))) -> To review
A11: 10 | B11: Sign-in | C11: docs/reports/evidence/ui/ar-mobile-sign-in.png docs/reports/evidence/ui/ar-desktop-sign-in.png | D11: signIn.create | E11: Create one | F11: أنشئ حسابًا | K11: =IF(G11="","To review",IF(AND(G11="Change",H11=""),"Add corrected text",IF(AND(H11<>"",J11<>"",ISERROR(SEARCH(J11,H11))),"Keep "&J11,""))) -> To review
A12: 11 | B12: Sign-in | C12: docs/reports/evidence/ui/ar-mobile-sign-in.png docs/reports/evidence/ui/ar-desktop-sign-in.png | D12: signIn.email | E12: Email address | F12: البريد الإلكتروني | K12: =IF(G12="","To review",IF(AND(G12="Change",H12=""),"Add corrected text",IF(AND(H12<>"",J12<>"",ISERROR(SEARCH(J12,H12))),"Keep "&J12,""))) -> To review
A13: 12 | B13: Sign-in | C13: docs/reports/evidence/ui/ar-mobile-sign-in.png docs/reports/evidence/ui/ar-desktop-sign-in.png | D13: signIn.forgot | E13: Forgot password? | F13: نسيت كلمة المرور؟ | K13: =IF(G13="","To review",IF(AND(G13="Change",H13=""),"Add corrected text",IF(AND(H13<>"",J13<>"",ISERROR(SEARCH(J13,H13))),"Keep "&J13,""))) -> To review
A14: 13 | B14: Sign-in | C14: docs/reports/evidence/ui/ar-mobile-sign-in.png docs/reports/evidence/ui/ar-desktop-sign-in.png | D14: signIn.invalid | E14: Email or password is incorrect. | F14: البريد الإلكتروني أو كلمة المرور غير صحيحة. | K14: =IF(G14="","To review",IF(AND(G14="Change",H14=""),"Add corrected text",IF(AND(H14<>"",J14<>"",ISERROR(SEARCH(J14,H14))),"Keep "&J14,""))) -> To review
A15: 14 | B15: Sign-in | C15: docs/reports/evidence/ui/ar-mobile-sign-in.png docs/reports/evidence/ui/ar-desktop-sign-in.png | D15: signIn.mfaHelp | E15: Enter the 6-digit code from your authenticator app. | F15: أدخل الرمز المكوّن من 6 أرقام من تطبيق المصادقة. | K15: =IF(G15="","To review",IF(AND(G15="Change",H15=""),"Add corrected text",IF(AND(H15<>"",J15<>"",ISERROR(SEARCH(J15,H15))),"Keep "&J15,""))) -> To review
A16: 15 | B16: Sign-in | C16: docs/reports/evidence/ui/ar-mobile-sign-in.png docs/reports/evidence/ui/ar-desktop-sign-in.png | D16: signIn.mfaTitle | E16: Two-step verification | F16: التحقق بخطوتين | K16: =IF(G16="","To review",IF(AND(G16="Change",H16=""),"Add corrected text",IF(AND(H16<>"",J16<>"",ISERROR(SEARCH(J16,H16))),"Keep "&J16,""))) -> To review
A17: 16 | B17: Sign-in | C17: docs/reports/evidence/ui/ar-mobile-sign-in.png docs/reports/evidence/ui/ar-desktop-sign-in.png | D17: signIn.noAccount | E17: Don't have an account? | F17: ليس لديك حساب؟ | K17: =IF(G17="","To review",IF(AND(G17="Change",H17=""),"Add corrected text",IF(AND(H17<>"",J17<>"",ISERROR(SEARCH(J17,H17))),"Keep "&J17,""))) -> To review
A18: 17 | B18: Sign-in | C18: docs/reports/evidence/ui/ar-mobile-sign-in.png docs/reports/evidence/ui/ar-desktop-sign-in.png | D18: signIn.password | E18: Password | F18: كلمة المرور | K18: =IF(G18="","To review",IF(AND(G18="Change",H18=""),"Add corrected text",IF(AND(H18<>"",J18<>"",ISERROR(SEARCH(J18,H18))),"Keep "&J18,""))) -> To review
A19: 18 | B19: Sign-in | C19: docs/reports/evidence/ui/ar-mobile-sign-in.png docs/reports/evidence/ui/ar-desktop-sign-in.png | D19: signIn.submit | E19: Sign in | F19: تسجيل الدخول | K19: =IF(G19="","To review",IF(AND(G19="Change",H19=""),"Add corrected text",IF(AND(H19<>"",J19<>"",ISERROR(SEARCH(J19,H19))),"Keep "&J19,""))) -> To review
A20: 19 | B20: Sign-in | C20: docs/reports/evidence/ui/ar-mobile-sign-in.png docs/reports/evidence/ui/ar-desktop-sign-in.png | D20: signIn.subtitle | E20: Your customer conversations, team and automations in one place. | F20: محادثات عملائك وفريقك وعمليات الأتمتة في مكان واحد. | K20: =IF(G20="","To review",IF(AND(G20="Change",H20=""),"Add corrected text",IF(AND(H20<>"",J20<>"",ISERROR(SEARCH(J20,H20))),"Keep "&J20,""))) -> To review
... A47: 46 | B47: Page not found | C47: No screenshot yet — open the page in Arabic on staging | D47: notFound.title | E47: Page not found | F47: الصفحة غير موجودة | K47: =IF(G47="","To review",IF(AND(G47="Change",H47=""),"Add corrected text",IF(AND(H47<>"",J47<>"",ISERROR(SEARCH(J47,H47))),"Keep "&J47,""))) -> To review
A48: 47 | B48: All app screens | C48: docs/reports/evidence/ui/ar-mobile-dashboard.png docs/reports/evidence/ui/ar-desktop-dashboard.png | D48: brand.by | E48: by Meronatic | F48: by Meronatic | I48: Kept in Latin script on purpose (brand lockup). Check only; no translation expected. | K48: =IF(G48="","To review",IF(AND(G48="Change",H48=""),"Add corrected text",IF(AND(H48<>"",J48<>"",ISERROR(SEARCH(J48,H48))),"Keep "&J48,""))) -> To review
A49: 48 | B49: All app screens | C49: docs/reports/evidence/ui/ar-mobile-dashboard.png docs/reports/evidence/ui/ar-desktop-dashboard.png | D49: common.error | E49: Something went wrong. Please try again. | F49: حدث خطأ ما. يُرجى المحاولة مرة أخرى. | K49: =IF(G49="","To review",IF(AND(G49="Change",H49=""),"Add corrected text",IF(AND(H49<>"",J49<>"",ISERROR(SEARCH(J49,H49))),"Keep "&J49,""))) -> To review
A50: 49 | B50: All app screens | C50: docs/reports/evidence/ui/ar-mobile-dashboard.png docs/reports/evidence/ui/ar-desktop-dashboard.png | D50: common.later | E50: Coming in a later phase | F50: متاح في مرحلة لاحقة | I50: Short badge next to menu items not yet available. Must stay short (fits beside the menu text). | K50: =IF(G50="","To review",IF(AND(G50="Change",H50=""),"Add corrected text",IF(AND(H50<>"",J50<>"",ISERROR(SEARCH(J50,H50))),"Keep "&J50,""))) -> To review
A51: 50 | B51: All app screens | C51: docs/reports/evidence/ui/ar-mobile-dashboard.png docs/reports/evidence/ui/ar-desktop-dashboard.png | D51: common.loading | E51: Loading… | F51: جارٍ التحميل… | K51: =IF(G51="","To review",IF(AND(G51="Change",H51=""),"Add corrected text",IF(AND(H51<>"",J51<>"",ISERROR(SEARCH(J51,H51))),"Keep "&J51,""))) -> To review
A52: 51 | B52: All app screens | C52: docs/reports/evidence/ui/ar-mobile-dashboard.png docs/reports/evidence/ui/ar-desktop-dashboard.png | D52: common.save | E52: Save changes | F52: حفظ التغييرات | K52: =IF(G52="","To review",IF(AND(G52="Change",H52=""),"Add corrected text",IF(AND(H52<>"",J52<>"",ISERROR(SEARCH(J52,H52))),"Keep "&J52,""))) -> To review
A53: 52 | B53: All app screens | C53: docs/reports/evidence/ui/ar-mobile-dashboard.png docs/reports/evidence/ui/ar-desktop-dashboard.png | D53: common.saved | E53: Changes saved | F53: تم حفظ التغييرات | K53: =IF(G53="","To review",IF(AND(G53="Change",H53=""),"Add corrected text",IF(AND(H53<>"",J53<>"",ISERROR(SEARCH(J53,H53))),"Keep "&J53,""))) -> To review
A54: 53 | B54: All app screens | C54: docs/reports/evidence/ui/ar-mobile-dashboard.png docs/reports/evidence/ui/ar-desktop-dashboard.png | D54: common.signOut | E54: Sign out | F54: تسجيل الخروج | K54: =IF(G54="","To review",IF(AND(G54="Change",H54=""),"Add corrected text",IF(AND(H54<>"",J54<>"",ISERROR(SEARCH(J54,H54))),"Keep "&J54,""))) -> To review
A55: 54 | B55: All app screens | C55: docs/reports/evidence/ui/ar-mobile-dashboard.png docs/reports/evidence/ui/ar-desktop-dashboard.png | D55: nav.automations | E55: Automations | F55: الأتمتة | K55: =IF(G55="","To review",IF(AND(G55="Change",H55=""),"Add corrected text",IF(AND(H55<>"",J55<>"",ISERROR(SEARCH(J55,H55))),"Keep "&J55,""))) -> To review
A56: 55 | B56: All app screens | C56: docs/reports/evidence/ui/ar-mobile-dashboard.png docs/reports/evidence/ui/ar-desktop-dashboard.png | D56: nav.campaigns | E56: Campaigns | F56: الحملات | K56: =IF(G56="","To review",IF(AND(G56="Change",H56=""),"Add corrected text",IF(AND(H56<>"",J56<>"",ISERROR(SEARCH(J56,H56))),"Keep "&J56,""))) -> To review
A57: 56 | B57: All app screens | C57: docs/reports/evidence/ui/ar-mobile-dashboard.png docs/reports/evidence/ui/ar-desktop-dashboard.png | D57: nav.company | E57: Company | F57: الشركة | K57: =IF(G57="","To review",IF(AND(G57="Change",H57=""),"Add corrected text",IF(AND(H57<>"",J57<>"",ISERROR(SEARCH(J57,H57))),"Keep "&J57,""))) -> To review
A58: 57 | B58: All app screens | C58: docs/reports/evidence/ui/ar-mobile-dashboard.png docs/reports/evidence/ui/ar-desktop-dashboard.png | D58: nav.contacts | E58: Contacts | F58: جهات الاتصال | K58: =IF(G58="","To review",IF(AND(G58="Change",H58=""),"Add corrected text",IF(AND(H58<>"",J58<>"",ISERROR(SEARCH(J58,H58))),"Keep "&J58,""))) -> To review
A59: 58 | B59: All app screens | C59: docs/reports/evidence/ui/ar-mobile-dashboard.png docs/reports/evidence/ui/ar-desktop-dashboard.png | D59: nav.dashboard | E59: Dashboard | F59: لوحة التحكم | K59: =IF(G59="","To review",IF(AND(G59="Change",H59=""),"Add corrected text",IF(AND(H59<>"",J59<>"",ISERROR(SEARCH(J59,H59))),"Keep "&J59,""))) -> To review
A60: 59 | B60: All app screens | C60: docs/reports/evidence/ui/ar-mobile-dashboard.png docs/reports/evidence/ui/ar-desktop-dashboard.png | D60: nav.inbox | E60: Inbox | F60: صندوق الوارد | K60: =IF(G60="","To review",IF(AND(G60="Change",H60=""),"Add corrected text",IF(AND(H60<>"",J60<>"",ISERROR(SEARCH(J60,H60))),"Keep "&J60,""))) -> To review
A61: 60 | B61: All app screens | C61: docs/reports/evidence/ui/ar-mobile-dashboard.png docs/reports/evidence/ui/ar-desktop-dashboard.png | D61: nav.main | E61: Main navigation | F61: التنقل الرئيسي | K61: =IF(G61="","To review",IF(AND(G61="Change",H61=""),"Add corrected text",IF(AND(H61<>"",J61<>"",ISERROR(SEARCH(J61,H61))),"Keep "&J61,""))) -> To review
A62: 61 | B62: All app screens | C62: docs/reports/evidence/ui/ar-mobile-dashboard.png docs/reports/evidence/ui/ar-desktop-dashboard.png | D62: nav.menu | E62: Menu | F62: القائمة | K62: =IF(G62="","To review",IF(AND(G62="Change",H62=""),"Add corrected text",IF(AND(H62<>"",J62<>"",ISERROR(SEARCH(J62,H62))),"Keep "&J62,""))) -> To review
... A72: 71 | B72: Dashboard | C72: docs/reports/evidence/ui/ar-mobile-dashboard.png docs/reports/evidence/ui/ar-desktop-dashboard.png | D72: dashboard.step3 | E72: Connect WhatsApp (Phase 2) | F72: اربط واتساب (المرحلة الثانية) | K72: =IF(G72="","To review",IF(AND(G72="Change",H72=""),"Add corrected text",IF(AND(H72<>"",J72<>"",ISERROR(SEARCH(J72,H72))),"Keep "&J72,""))) -> To review
A73: 72 | B73: Dashboard | C73: docs/reports/evidence/ui/ar-mobile-dashboard.png docs/reports/evidence/ui/ar-desktop-dashboard.png | D73: dashboard.trial | E73: Trial ends on {date} | F73: تنتهي الفترة التجريبية في {date} | I73: {date} is replaced by a date such as 2 نوفمبر 2026. | J73: {date} | K73: =IF(G73="","To review",IF(AND(G73="Change",H73=""),"Add corrected text",IF(AND(H73<>"",J73<>"",ISERROR(SEARCH(J73,H73))),"Keep "&J73,""))) -> To review
A74: 73 | B74: Dashboard | C74: docs/reports/evidence/ui/ar-mobile-dashboard.png docs/reports/evidence/ui/ar-desktop-dashboard.png | D74: dashboard.welcome | E74: Welcome, {name} | F74: مرحبًا، {name} | I74: {name} is replaced by the person's name. | J74: {name} | K74: =IF(G74="","To review",IF(AND(G74="Change",H74=""),"Add corrected text",IF(AND(H74<>"",J74<>"",ISERROR(SEARCH(J74,H74))),"Keep "&J74,""))) -> To review
A75: 74 | B75: Company settings | C75: docs/reports/evidence/ui/ar-mobile-company-settings.png docs/reports/evidence/ui/ar-desktop-company-settings.png | D75: company.close | E75: Closes | F75: يغلق | K75: =IF(G75="","To review",IF(AND(G75="Change",H75=""),"Add corrected text",IF(AND(H75<>"",J75<>"",ISERROR(SEARCH(J75,H75))),"Keep "&J75,""))) -> To review
...

Sheet Summary
A1: Screen | B1: Rows | C1: Reviewed | D1: OK | E1: Change | F1: Question | G1: Left to review | H1: Changes applied
A2: Sign-in | B2: =COUNTIFS(Review!$B$2:$B$105,A2) -> 23 | C2: =COUNTIFS(Review!$B$2:$B$105,A2,Review!$G$2:$G$105,"<>") -> 0 | D2: =COUNTIFS(Review!$B$2:$B$105,A2,Review!$G$2:$G$105,"OK") -> 0 | E2: =COUNTIFS(Review!$B$2:$B$105,A2,Review!$G$2:$G$105,"Change") -> 0 | F2: =COUNTIFS(Review!$B$2:$B$105,A2,Review!$G$2:$G$105,"Question") -> 0 | G2: =B2-C2 -> 23 | H2: =COUNTIFS(Review!$B$2:$B$105,A2,Review!$L$2:$L$105,"Applied") -> 0
A3: Sign-up | B3: =COUNTIFS(Review!$B$2:$B$105,A3) -> 9 | C3: =COUNTIFS(Review!$B$2:$B$105,A3,Review!$G$2:$G$105,"<>") -> 0 | D3: =COUNTIFS(Review!$B$2:$B$105,A3,Review!$G$2:$G$105,"OK") -> 0 | E3: =COUNTIFS(Review!$B$2:$B$105,A3,Review!$G$2:$G$105,"Change") -> 0 | F3: =COUNTIFS(Review!$B$2:$B$105,A3,Review!$G$2:$G$105,"Question") -> 0 | G3: =B3-C3 -> 9 | H3: =COUNTIFS(Review!$B$2:$B$105,A3,Review!$L$2:$L$105,"Applied") -> 0
A4: Forgot password | B4: =COUNTIFS(Review!$B$2:$B$105,A4) -> 3 | C4: =COUNTIFS(Review!$B$2:$B$105,A4,Review!$G$2:$G$105,"<>") -> 0 | D4: =COUNTIFS(Review!$B$2:$B$105,A4,Review!$G$2:$G$105,"OK") -> 0 | E4: =COUNTIFS(Review!$B$2:$B$105,A4,Review!$G$2:$G$105,"Change") -> 0 | F4: =COUNTIFS(Review!$B$2:$B$105,A4,Review!$G$2:$G$105,"Question") -> 0 | G4: =B4-C4 -> 3 | H4: =COUNTIFS(Review!$B$2:$B$105,A4,Review!$L$2:$L$105,"Applied") -> 0
A5: Verify email | B5: =COUNTIFS(Review!$B$2:$B$105,A5) -> 3 | C5: =COUNTIFS(Review!$B$2:$B$105,A5,Review!$G$2:$G$105,"<>") -> 0 | D5: =COUNTIFS(Review!$B$2:$B$105,A5,Review!$G$2:$G$105,"OK") -> 0 | E5: =COUNTIFS(Review!$B$2:$B$105,A5,Review!$G$2:$G$105,"Change") -> 0 | F5: =COUNTIFS(Review!$B$2:$B$105,A5,Review!$G$2:$G$105,"Question") -> 0 | G5: =B5-C5 -> 3 | H5: =COUNTIFS(Review!$B$2:$B$105,A5,Review!$L$2:$L$105,"Applied") -> 0
A6: Reset password | B6: =COUNTIFS(Review!$B$2:$B$105,A6) -> 5 | C6: =COUNTIFS(Review!$B$2:$B$105,A6,Review!$G$2:$G$105,"<>") -> 0 | D6: =COUNTIFS(Review!$B$2:$B$105,A6,Review!$G$2:$G$105,"OK") -> 0 | E6: =COUNTIFS(Review!$B$2:$B$105,A6,Review!$G$2:$G$105,"Change") -> 0 | F6: =COUNTIFS(Review!$B$2:$B$105,A6,Review!$G$2:$G$105,"Question") -> 0 | G6: =B6-C6 -> 5 | H6: =COUNTIFS(Review!$B$2:$B$105,A6,Review!$L$2:$L$105,"Applied") -> 0
A7: Page not found | B7: =COUNTIFS(Review!$B$2:$B$105,A7) -> 3 | C7: =COUNTIFS(Review!$B$2:$B$105,A7,Review!$G$2:$G$105,"<>") -> 0 | D7: =COUNTIFS(Review!$B$2:$B$105,A7,Review!$G$2:$G$105,"OK") -> 0 | E7: =COUNTIFS(Review!$B$2:$B$105,A7,Review!$G$2:$G$105,"Change") -> 0 | F7: =COUNTIFS(Review!$B$2:$B$105,A7,Review!$G$2:$G$105,"Question") -> 0 | G7: =B7-C7 -> 3 | H7: =COUNTIFS(Review!$B$2:$B$105,A7,Review!$L$2:$L$105,"Applied") -> 0
A8: All app screens | B8: =COUNTIFS(Review!$B$2:$B$105,A8) -> 18 | C8: =COUNTIFS(Review!$B$2:$B$105,A8,Review!$G$2:$G$105,"<>") -> 0 | D8: =COUNTIFS(Review!$B$2:$B$105,A8,Review!$G$2:$G$105,"OK") -> 0 | E8: =COUNTIFS(Review!$B$2:$B$105,A8,Review!$G$2:$G$105,"Change") -> 0 | F8: =COUNTIFS(Review!$B$2:$B$105,A8,Review!$G$2:$G$105,"Question") -> 0 | G8: =B8-C8 -> 18 | H8: =COUNTIFS(Review!$B$2:$B$105,A8,Review!$L$2:$L$105,"Applied") -> 0
A9: Dashboard | B9: =COUNTIFS(Review!$B$2:$B$105,A9) -> 9 | C9: =COUNTIFS(Review!$B$2:$B$105,A9,Review!$G$2:$G$105,"<>") -> 0 | D9: =COUNTIFS(Review!$B$2:$B$105,A9,Review!$G$2:$G$105,"OK") -> 0 | E9: =COUNTIFS(Review!$B$2:$B$105,A9,Review!$G$2:$G$105,"Change") -> 0 | F9: =COUNTIFS(Review!$B$2:$B$105,A9,Review!$G$2:$G$105,"Question") -> 0 | G9: =B9-C9 -> 9 | H9: =COUNTIFS(Review!$B$2:$B$105,A9,Review!$L$2:$L$105,"Applied") -> 0
A10: Company settings | B10: =COUNTIFS(Review!$B$2:$B$105,A10) -> 20 | C10: =COUNTIFS(Review!$B$2:$B$105,A10,Review!$G$2:$G$105,"<>") -> 0 | D10: =COUNTIFS(Review!$B$2:$B$105,A10,Review!$G$2:$G$105,"OK") -> 0 | E10: =COUNTIFS(Review!$B$2:$B$105,A10,Review!$G$2:$G$105,"Change") -> 0 | F10: =COUNTIFS(Review!$B$2:$B$105,A10,Review!$G$2:$G$105,"Question") -> 0 | G10: =B10-C10 -> 20 | H10: =COUNTIFS(Review!$B$2:$B$105,A10,Review!$L$2:$L$105,"Applied") -> 0
A11: Team and roles | B11: =COUNTIFS(Review!$B$2:$B$105,A11) -> 11 | C11: =COUNTIFS(Review!$B$2:$B$105,A11,Review!$G$2:$G$105,"<>") -> 0 | D11: =COUNTIFS(Review!$B$2:$B$105,A11,Review!$G$2:$G$105,"OK") -> 0 | E11: =COUNTIFS(Review!$B$2:$B$105,A11,Review!$G$2:$G$105,"Change") -> 0 | F11: =COUNTIFS(Review!$B$2:$B$105,A11,Review!$G$2:$G$105,"Question") -> 0 | G11: =B11-C11 -> 11 | H11: =COUNTIFS(Review!$B$2:$B$105,A11,Review!$L$2:$L$105,"Applied") -> 0
A12: Total | B12: =SUM(B2:B11) -> 104 | C12: =SUM(C2:C11) -> 0 | D12: =SUM(D2:D11) -> 0 | E12: =SUM(E2:E11) -> 0 | F12: =SUM(F2:F11) -> 0 | G12: =SUM(G2:G11) -> 104 | H12: =SUM(H2:H11) -> 0
